<?xml version="1.0" encoding="utf-8"?>
<!-- This URDF was automatically created by SolidWorks to URDF Exporter! Originally created by Stephen Brawner (brawner@gmail.com) 
     Commit Version: 1.6.0-4-g7f85cfe  Build Version: 1.6.7995.38578
     For more information, please see http://wiki.ros.org/sw_urdf_exporter -->
<robot
  name="armmu">
  <link
    name="base_link">
    <inertial>
      <origin
        xyz="-0.0049906 0.001504 0.0005019"
        rpy="0 0 0" />
      <mass
        value="0.16229" />
      <inertia
        ixx="0.00017754"
        ixy="-2.6436E-07"
        ixz="2.077E-07"
        iyy="0.00019628"
        iyz="-7.3089E-06"
        izz="0.00016048" />
    </inertial>
    <visual>
      <origin
        xyz="0 0 0"
        rpy="0 0 0" />
      <geometry>
        <mesh
          filename="package://armmu/meshes/base_link.STL" />
      </geometry>
      <material
        name="">
        <color
          rgba="1 1 1 1" />
      </material>
    </visual>
    <collision>
      <origin
        xyz="0 0 0"
        rpy="0 0 0" />
      <geometry>
        <mesh
          filename="package://armmu/meshes/base_link.STL" />
      </geometry>
    </collision>
  </link>
  <link
    name="Link1">
    <inertial>
      <origin
        xyz="-0.001121 0.033927 -0.00037542"
        rpy="0 0 0" />
      <mass
        value="0.10688" />
      <inertia
        ixx="7.7882E-05"
        ixy="-2.6155E-06"
        ixz="2.3433E-07"
        iyy="8.3471E-05"
        iyz="-2.4748E-07"
        izz="9.2224E-05" />
    </inertial>
    <visual>
      <origin
        xyz="0 0 0"
        rpy="0 0 0" />
      <geometry>
        <mesh
          filename="package://armmu/meshes/Link1.STL" />
      </geometry>
      <material
        name="">
        <color
          rgba="1 1 1 1" />
      </material>
    </visual>
    <collision>
      <origin
        xyz="0 0 0"
        rpy="0 0 0" />
      <geometry>
        <mesh
          filename="package://armmu/meshes/Link1.STL" />
      </geometry>
    </collision>
  </link>
  <joint
    name="joint1"
    type="continuous">
    <origin
      xyz="-0.0049371 0.00925 0.038437"
      rpy="1.5708 0 -0.29706" />
    <parent
      link="base_link" />
    <child
      link="Link1" />
    <axis
      xyz="0 1 0" />
    <limit
      lower="-3.14"
      upper="3.14"
      effort="100"
      velocity="1" />
  </joint>
  <link
    name="Link2">
    <inertial>
      <origin
        xyz="-0.0076562 0.0047022 0.15043"
        rpy="0 0 0" />
      <mass
        value="0.20392" />
      <inertia
        ixx="0.0016275"
        ixy="6.8723E-06"
        ixz="3.9371E-06"
        iyy="0.0016918"
        iyz="-0.00012712"
        izz="0.00023921" />
    </inertial>
    <visual>
      <origin
        xyz="0 0 0"
        rpy="0 0 0" />
      <geometry>
        <mesh
          filename="package://armmu/meshes/Link2.STL" />
      </geometry>
      <material
        name="">
        <color
          rgba="1 1 1 1" />
      </material>
    </visual>
    <collision>
      <origin
        xyz="0 0 0"
        rpy="0 0 0" />
      <geometry>
        <mesh
          filename="package://armmu/meshes/Link2.STL" />
      </geometry>
    </collision>
  </link>
  <joint
    name="joint2"
    type="continuous">
    <origin
      xyz="0 0.043 0"
      rpy="-0.78465 0 0" />
    <parent
      link="Link1" />
    <child
      link="Link2" />
    <axis
      xyz="-1 0 0" />
    <limit
      lower="-3.14"
      upper="3.14"
      effort="100"
      velocity="1" />
  </joint>
  <link
    name="Link3">
    <inertial>
      <origin
        xyz="-0.00043323 0.024114 -0.10205"
        rpy="0 0 0" />
      <mass
        value="0.25929" />
      <inertia
        ixx="0.00020923"
        ixy="5.8493E-07"
        ixz="-9.9948E-07"
        iyy="0.00018257"
        iyz="1.5246E-05"
        izz="9.7294E-05" />
    </inertial>
    <visual>
      <origin
        xyz="0 0 0"
        rpy="0 0 0" />
      <geometry>
        <mesh
          filename="package://armmu/meshes/Link3.STL" />
      </geometry>
      <material
        name="">
        <color
          rgba="1 1 1 1" />
      </material>
    </visual>
    <collision>
      <origin
        xyz="0 0 0"
        rpy="0 0 0" />
      <geometry>
        <mesh
          filename="package://armmu/meshes/Link3.STL" />
      </geometry>
    </collision>
  </link>
  <joint
    name="joint3"
    type="continuous">
    <origin
      xyz="0 0.038605 0.2824"
      rpy="1.4749 0 0" />
    <parent
      link="Link2" />
    <child
      link="Link3" />
    <axis
      xyz="-1 0 0" />
    <limit
      lower="-3.14"
      upper="3.14"
      effort="100"
      velocity="1" />
  </joint>
  <link
    name="Link4">
    <inertial>
      <origin
        xyz="0.00107635274212739 0.000824369137569558 -0.00710818442435024"
        rpy="0 0 0" />
      <mass
        value="0.120706822170496" />
      <inertia
        ixx="4.59017245988586E-05"
        ixy="-3.76106949082763E-08"
        ixz="-7.20048589622133E-08"
        iyy="3.66448805551282E-05"
        iyz="-2.53060525186735E-07"
        izz="3.89787401023863E-05" />
    </inertial>
    <visual>
      <origin
        xyz="0 0 0"
        rpy="0 0 0" />
      <geometry>
        <mesh
          filename="package://armmu/meshes/Link4.STL" />
      </geometry>
      <material
        name="">
        <color
          rgba="1 1 1 1" />
      </material>
    </visual>
    <collision>
      <origin
        xyz="0 0 0"
        rpy="0 0 0" />
      <geometry>
        <mesh
          filename="package://armmu/meshes/Link4.STL" />
      </geometry>
    </collision>
  </link>
  <joint
    name="joint4"
    type="continuous">
    <origin
      xyz="0 0.042715 -0.23598"
      rpy="-0.17245 0.019034 -2.9223" />
    <parent
      link="Link3" />
    <child
      link="Link4" />
    <axis
      xyz="0 -0.087161 0.99619" />
    <limit
      lower="-3.14"
      upper="3.14"
      effort="100"
      velocity="1" />
  </joint>
  <link
    name="Link5">
    <inertial>
      <origin
        xyz="0.0016938 0.0083734 -0.094123"
        rpy="0 0 0" />
      <mass
        value="0.29225" />
      <inertia
        ixx="0.00015798"
        ixy="-6.905E-08"
        ixz="-2.437E-05"
        iyy="0.00022382"
        iyz="2.8075E-06"
        izz="0.00018803" />
    </inertial>
    <visual>
      <origin
        xyz="0 0 0"
        rpy="0 0 0" />
      <geometry>
        <mesh
          filename="package://armmu/meshes/Link5.STL" />
      </geometry>
      <material
        name="">
        <color
          rgba="1 1 1 1" />
      </material>
    </visual>
    <collision>
      <origin
        xyz="0 0 0"
        rpy="0 0 0" />
      <geometry>
        <mesh
          filename="package://armmu/meshes/Link5.STL" />
      </geometry>
    </collision>
  </link>
  <joint
    name="joint5"
    type="continuous">
    <origin
      xyz="0 0.001041 -0.011898"
      rpy="1.022 0 0" />
    <parent
      link="Link4" />
    <child
      link="Link5" />
    <axis
      xyz="-1 0 0" />
    <limit
      lower="-3.14"
      upper="3.14"
      effort="100"
      velocity="1" />
  </joint>
  <link
    name="Link6">
    <inertial>
      <origin
        xyz="-1.078E-06 -0.0079358 1.396E-06"
        rpy="0 0 0" />
      <mass
        value="0.0050886" />
      <inertia
        ixx="5.534E-07"
        ixy="1.3344E-11"
        ixz="1.5837E-07"
        iyy="9.9659E-07"
        iyz="-1.7332E-11"
        izz="4.6806E-07" />
    </inertial>
    <visual>
      <origin
        xyz="0 0 0"
        rpy="0 0 0" />
      <geometry>
        <mesh
          filename="package://armmu/meshes/Link6.STL" />
      </geometry>
      <material
        name="">
        <color
          rgba="0.79216 0.81961 0.93333 1" />
      </material>
    </visual>
    <collision>
      <origin
        xyz="0 0 0"
        rpy="0 0 0" />
      <geometry>
        <mesh
          filename="package://armmu/meshes/Link6.STL" />
      </geometry>
    </collision>
  </link>
  <joint
    name="joint6"
    type="continuous">
    <origin
      xyz="0 0.012403 -0.14176"
      rpy="1.5569 0.086158 -1.7311" />
    <parent
      link="Link5" />
    <child
      link="Link6" />
    <axis
      xyz="0 -1 0" />
    <limit
      lower="-3.14"
      upper="3.14"
      effort="100"
      velocity="1" />
  </joint>
</robot>